<?xml version="1.0" ?>
<!-- =================================================================================== -->
<!-- |    This document was autogenerated by xacro from antonie.urdf.xacro             | -->
<!-- |    EDITING THIS FILE BY HAND IS NOT RECOMMENDED                                 | -->
<!-- =================================================================================== -->
<robot name="antonie">
  
  <link name="base_link">
    <inertial>
      <mass value="5.0"/>
      <origin xyz="0 0 0" rpy="0 0 0"/>
      <inertia ixx="0.1" ixy="0.0" ixz="0.0" iyy="0.1" iyz="0.0" izz="0.1"/>
    </inertial>
    <visual>
      <geometry>
        <cylinder length="0.6" radius="0.2"/>
      </geometry>
      <material name="red">
        <color rgba="1.0 0.0 0.0 1.0"/>
      </material>
    </visual>
    <collision>
      <geometry>
        <cylinder length="0.6" radius="0.2"/>
      </geometry>
    </collision>
  </link>

  <link name="link_1">
    <inertial>
      <mass value="2.0"/>
      <origin xyz="0 0 0.25" rpy="0 0 0"/>
      <inertia ixx="0.05" ixy="0.0" ixz="0.0" iyy="0.05" iyz="0.0" izz="0.01"/>
    </inertial>
    <visual>
      <origin xyz="0 0 0.25"/>
      <geometry>
        <cylinder length="0.5" radius="0.1"/>
      </geometry>
      <material name="white">
        <color rgba="1.0 1.0 1.0 1.0"/>
      </material>
    </visual>
    <collision>
      <origin xyz="0 0 0.25"/>
      <geometry>
        <cylinder length="0.5" radius="0.1"/>
      </geometry>
    </collision>
  </link>

  <link name="link_2">
    <inertial>
      <mass value="1.5"/>
      <origin xyz="0 0 0.25" rpy="0 0 0"/>
      <inertia ixx="0.03" ixy="0.0" ixz="0.0" iyy="0.03" iyz="0.0" izz="0.005"/>
    </inertial>
    <visual>
      <origin xyz="0 0 0.25"/>
      <geometry>
        <cylinder length="0.5" radius="0.08"/>
      </geometry>
      <material name="red">
        <color rgba="1.0 0.0 0.0 1.0"/>
      </material>
    </visual>
    <collision>
      <origin xyz="0 0 0.25"/>
      <geometry>
        <cylinder length="0.5" radius="0.08"/>
      </geometry>
    </collision>
  </link>

  <link name="link_3">
    <inertial>
      <mass value="1.0"/>
      <origin xyz="0 0 0.2" rpy="0 0 0"/>
      <inertia ixx="0.015" ixy="0.0" ixz="0.0" iyy="0.015" iyz="0.0" izz="0.002"/>
    </inertial>
    <visual>
      <origin xyz="0 0 0.2"/>
      <geometry>
        <cylinder length="0.4" radius="0.06"/>
      </geometry>
      <material name="white">
        <color rgba="1.0 1.0 1.0 1.0"/>
      </material>
    </visual>
    <collision>
      <origin xyz="0 0 0.2"/>
      <geometry>
        <cylinder length="0.4" radius="0.06"/>
      </geometry>
    </collision>
  </link>

  <link name="gripper_base">
    <inertial>
      <mass value="0.5"/>
      <origin xyz="0 0 0" rpy="0 0 0"/>
      <inertia ixx="0.002" ixy="0.0" ixz="0.0" iyy="0.002" iyz="0.0" izz="0.002"/>
    </inertial>
    <visual>
      <geometry>
        <box size="0.2 0.05 0.05"/>
      </geometry>
      <material name="yellow">
        <color rgba="1.0 1.0 0.0 1.0"/>
      </material>
    </visual>
    <collision>
      <geometry>
        <box size="0.2 0.05 0.05"/>
      </geometry>
    </collision>
  </link>

  <link name="left_finger">
    <inertial>
      <mass value="0.1"/>
      <origin xyz="0 0 0.05" rpy="0 0 0"/>
      <inertia ixx="0.0001" ixy="0.0" ixz="0.0" iyy="0.0001" iyz="0.0" izz="0.0001"/>
    </inertial>
    <visual>
      <origin xyz="0 0 0.05"/>
      <geometry>
        <box size="0.02 0.02 0.1"/>
      </geometry>
      <material name="yellow"/>
    </visual>
    <collision>
      <origin xyz="0 0 0.05"/>
      <geometry>
        <box size="0.02 0.02 0.1"/>
      </geometry>
    </collision>
  </link>

  <link name="right_finger">
    <inertial>
      <mass value="0.1"/>
      <origin xyz="0 0 0.05" rpy="0 0 0"/>
      <inertia ixx="0.0001" ixy="0.0" ixz="0.0" iyy="0.0001" iyz="0.0" izz="0.0001"/>
    </inertial>
    <visual>
      <origin xyz="0 0 0.05"/>
      <geometry>
        <box size="0.02 0.02 0.1"/>
      </geometry>
      <material name="yellow"/>
    </visual>
    <collision>
      <origin xyz="0 0 0.05"/>
      <geometry>
        <box size="0.02 0.02 0.1"/>
      </geometry>
    </collision>
  </link>

  <joint name="arm_0_joint" type="revolute">
    <parent link="base_link"/>
    <child link="link_1"/>
    <origin xyz="0 0 0.3"/>
    <axis xyz="0 0 1"/>
    <limit effort="10" lower="-3.14" upper="3.14" velocity="1.0"/>
  </joint>

  <joint name="arm_1_joint" type="revolute">
    <parent link="link_1"/>
    <child link="link_2"/>
    <origin xyz="0 0 0.5"/>
    <axis xyz="0 1 0"/>
    <limit effort="10" lower="-1.57" upper="1.57" velocity="1.0"/>
  </joint>

  <joint name="arm_2_joint" type="revolute">
    <parent link="link_2"/>
    <child link="link_3"/>
    <origin xyz="0 0 0.5"/>
    <axis xyz="0 1 0"/>
    <limit effort="10" lower="-1.57" upper="1.57" velocity="1.0"/>
  </joint>

  <joint name="gripper_fixed_joint" type="fixed">
    <parent link="link_3"/>
    <child link="gripper_base"/>
    <origin rpy="0 0 0" xyz="0 0 0.4"/>
  </joint>

  <joint name="gripper_1_joint" type="prismatic">
    <parent link="gripper_base"/>
    <child link="left_finger"/>
    <origin xyz="-0.08 0 0"/>
    <axis xyz="1 0 0"/>
    <limit effort="5" lower="0.0" upper="0.05" velocity="0.5"/>
  </joint>

  <joint name="gripper_2_joint" type="prismatic">
    <parent link="gripper_base"/>
    <child link="right_finger"/>
    <origin xyz="0.08 0 0"/>
    <axis xyz="-1 0 0"/>
    <limit effort="5" lower="0.0" upper="0.05" velocity="0.5"/>
  </joint>

  <ros2_control name="FakeSystem" type="system">
    <hardware>
      <plugin>gz_ros2_control/GazeboSimSystem</plugin>
    </hardware>
    <joint name="arm_0_joint">
      <command_interface name="position"/>
      <state_interface name="position">
        <param name="initial_value">0</param>
      </state_interface>
      <state_interface name="velocity"/>
    </joint>
    <joint name="arm_1_joint">
      <command_interface name="position"/>
      <state_interface name="position">
        <param name="initial_value">0</param>
      </state_interface>
      <state_interface name="velocity"/>
    </joint>
    <joint name="arm_2_joint">
      <command_interface name="position"/>
      <state_interface name="position">
        <param name="initial_value">0</param>
      </state_interface>
      <state_interface name="velocity"/>
    </joint>
    <joint name="gripper_1_joint">
      <command_interface name="position"/>
      <state_interface name="position">
        <param name="initial_value">0</param>
      </state_interface>
      <state_interface name="velocity"/>
    </joint>
    <joint name="gripper_2_joint">
      <command_interface name="position"/>
      <state_interface name="position">
        <param name="initial_value">0</param>
      </state_interface>
      <state_interface name="velocity"/>
    </joint>
  </ros2_control>

  <gazebo>
    <plugin filename="libgz_ros2_control-system.so" name="gz_ros2_control::GazeboSimROS2ControlPlugin">
      <parameters>/home/user/ros2_ws/install/antonie_moveit_config/share/antonie_moveit_config/config/ros2_controllers.yaml</parameters>
      <controller_manager_name>controller_manager</controller_manager_name>
    </plugin>
  </gazebo>
</robot>
